[32m2023-12-16 07:48:05 -0500[0m - dagster - [34mDEBUG[0m - __ASSET_JOB - 2a348aac-a832-40cd-8794-b3a7e2ff8b37 - 68245 - LOGS_CAPTURED - Started capturing logs in process (pid: 68245).
[32m2023-12-16 07:48:05 -0500[0m - dagster - [34mDEBUG[0m - __ASSET_JOB - 2a348aac-a832-40cd-8794-b3a7e2ff8b37 - 68245 - house_reps_download - STEP_START - Started execution of step "house_reps_download".
[32m2023-12-16 07:48:05 -0500[0m - dagster - [34mERROR[0m - [31m__ASSET_JOB - 2a348aac-a832-40cd-8794-b3a7e2ff8b37 - 68245 - house_reps_download - STEP_FAILURE - Execution of step "house_reps_download" failed.

dagster._core.errors.DagsterExecutionStepExecutionError: Error occurred while executing op "house_reps_download"::

AttributeError: 'Repo' object has no attribute 'pull'

Stack Trace:
  File "/Users/felix/Projects/codenym/DataPipelines/.venv/lib/python3.11/site-packages/dagster/_core/execution/plan/utils.py", line 54, in op_execution_error_boundary
    yield
  File "/Users/felix/Projects/codenym/DataPipelines/.venv/lib/python3.11/site-packages/dagster/_utils/__init__.py", line 465, in iterate_with_context
    next_output = next(iterator)
                  ^^^^^^^^^^^^^^
  File "/Users/felix/Projects/codenym/DataPipelines/.venv/lib/python3.11/site-packages/dagster/_core/execution/plan/compute_generator.py", line 131, in _coerce_op_compute_fn_to_iterator
    result = invoke_compute_fn(
             ^^^^^^^^^^^^^^^^^^
  File "/Users/felix/Projects/codenym/DataPipelines/.venv/lib/python3.11/site-packages/dagster/_core/execution/plan/compute_generator.py", line 125, in invoke_compute_fn
    return fn(context, **args_to_pass) if context_arg_provided else fn(**args_to_pass)
                                                                    ^^^^^^^^^^^^^^^^^^
  File "/Users/felix/Projects/codenym/DataPipelines/datanym/assets/HouseVotes/house_votes.py", line 143, in house_reps_download
    repo.pull()
    ^^^^^^^^^
[0m
